Workbook

Sheet DASHBOARD
C1: NexusRH CI — Cahier de Recettes Officiel OpenLab Consulting · v1.0
C3: Mis à jour le 25/10/2026 · Couverture cible : 100% des fonctionnalités · statut vide = non exécuté
A5: RÉSUMÉ PAR MODULE
A6: Module | B6: Total | C6: ✅ Passé | D6: ❌ Échoué | E6: ⚠️ Bloqué | F6: ▶️ En cours | G6: ⬜ Non exécuté | H6: % Réussite | I6: Statut
A7: Authentification | B7: =COUNTA('AUTH'!A:A)-2 | C7: =COUNTIF('AUTH'!I:I,"✅ Passé") | D7: =COUNTIF('AUTH'!I:I,"❌ Échoué") | E7: =COUNTIF('AUTH'!I:I,"⚠️ Bloqué") | F7: =COUNTIF('AUTH'!I:I,"▶️ En cours") | G7: =B7-SUM(C7:F7) | H7: =IF(B7=0,0,C7/B7) | I7: =IF(H7=1,"🟢 Complet",IF(H7>0.7,"🟡 Avancé",IF(H7>0,"🟠 En cours","⬜ À faire")))
A8: Portail Super Admin | B8: =COUNTA('PLT'!A:A)-2 | C8: =COUNTIF('PLT'!I:I,"✅ Passé") | D8: =COUNTIF('PLT'!I:I,"❌ Échoué") | E8: =COUNTIF('PLT'!I:I,"⚠️ Bloqué") | F8: =COUNTIF('PLT'!I:I,"▶️ En cours") | G8: =B8-SUM(C8:F8) | H8: =IF(B8=0,0,C8/B8) | I8: =IF(H8=1,"🟢 Complet",IF(H8>0.7,"🟡 Avancé",IF(H8>0,"🟠 En cours","⬜ À faire")))
A9: Employés & contrats | B9: =COUNTA('EMP'!A:A)-2 | C9: =COUNTIF('EMP'!I:I,"✅ Passé") | D9: =COUNTIF('EMP'!I:I,"❌ Échoué") | E9: =COUNTIF('EMP'!I:I,"⚠️ Bloqué") | F9: =COUNTIF('EMP'!I:I,"▶️ En cours") | G9: =B9-SUM(C9:F9) | H9: =IF(B9=0,0,C9/B9) | I9: =IF(H9=1,"🟢 Complet",IF(H9>0.7,"🟡 Avancé",IF(H9>0,"🟠 En cours","⬜ À faire")))
A10: Paie CI (CNPS+ITS) | B10: =COUNTA('PAY'!A:A)-2 | C10: =COUNTIF('PAY'!I:I,"✅ Passé") | D10: =COUNTIF('PAY'!I:I,"❌ Échoué") | E10: =COUNTIF('PAY'!I:I,"⚠️ Bloqué") | F10: =COUNTIF('PAY'!I:I,"▶️ En cours") | G10: =B10-SUM(C10:F10) | H10: =IF(B10=0,0,C10/B10) | I10: =IF(H10=1,"🟢 Complet",IF(H10>0.7,"🟡 Avancé",IF(H10>0,"🟠 En cours","⬜ À faire")))
A11: Absences & congés | B11: =COUNTA('ABS'!A:A)-2 | C11: =COUNTIF('ABS'!I:I,"✅ Passé") | D11: =COUNTIF('ABS'!I:I,"❌ Échoué") | E11: =COUNTIF('ABS'!I:I,"⚠️ Bloqué") | F11: =COUNTIF('ABS'!I:I,"▶️ En cours") | G11: =B11-SUM(C11:F11) | H11: =IF(B11=0,0,C11/B11) | I11: =IF(H11=1,"🟢 Complet",IF(H11>0.7,"🟡 Avancé",IF(H11>0,"🟠 En cours","⬜ À faire")))
A12: Recrutement | B12: =COUNTA('REC'!A:A)-2 | C12: =COUNTIF('REC'!I:I,"✅ Passé") | D12: =COUNTIF('REC'!I:I,"❌ Échoué") | E12: =COUNTIF('REC'!I:I,"⚠️ Bloqué") | F12: =COUNTIF('REC'!I:I,"▶️ En cours") | G12: =B12-SUM(C12:F12) | H12: =IF(B12=0,0,C12/B12) | I12: =IF(H12=1,"🟢 Complet",IF(H12>0.7,"🟡 Avancé",IF(H12>0,"🟠 En cours","⬜ À faire")))
A13: Sourcing IA | B13: =COUNTA('SRC'!A:A)-2 | C13: =COUNTIF('SRC'!I:I,"✅ Passé") | D13: =COUNTIF('SRC'!I:I,"❌ Échoué") | E13: =COUNTIF('SRC'!I:I,"⚠️ Bloqué") | F13: =COUNTIF('SRC'!I:I,"▶️ En cours") | G13: =B13-SUM(C13:F13) | H13: =IF(B13=0,0,C13/B13) | I13: =IF(H13=1,"🟢 Complet",IF(H13>0.7,"🟡 Avancé",IF(H13>0,"🟠 En cours","⬜ À faire")))
A14: Multi-pays & filiales | B14: =COUNTA('MPF'!A:A)-2 | C14: =COUNTIF('MPF'!I:I,"✅ Passé") | D14: =COUNTIF('MPF'!I:I,"❌ Échoué") | E14: =COUNTIF('MPF'!I:I,"⚠️ Bloqué") | F14: =COUNTIF('MPF'!I:I,"▶️ En cours") | G14: =B14-SUM(C14:F14) | H14: =IF(B14=0,0,C14/B14) | I14: =IF(H14=1,"🟢 Complet",IF(H14>0.7,"🟡 Avancé",IF(H14>0,"🟠 En cours","⬜ À faire")))
A15: Formation / FDFP | B15: =COUNTA('FRM'!A:A)-2 | C15: =COUNTIF('FRM'!I:I,"✅ Passé") | D15: =COUNTIF('FRM'!I:I,"❌ Échoué") | E15: =COUNTIF('FRM'!I:I,"⚠️ Bloqué") | F15: =COUNTIF('FRM'!I:I,"▶️ En cours") | G15: =B15-SUM(C15:F15) | H15: =IF(B15=0,0,C15/B15) | I15: =IF(H15=1,"🟢 Complet",IF(H15>0.7,"🟡 Avancé",IF(H15>0,"🟠 En cours","⬜ À faire")))
A16: Notes de Frais | B16: =COUNTA('FRA'!A:A)-2 | C16: =COUNTIF('FRA'!I:I,"✅ Passé") | D16: =COUNTIF('FRA'!I:I,"❌ Échoué") | E16: =COUNTIF('FRA'!I:I,"⚠️ Bloqué") | F16: =COUNTIF('FRA'!I:I,"▶️ En cours") | G16: =B16-SUM(C16:F16) | H16: =IF(B16=0,0,C16/B16) | I16: =IF(H16=1,"🟢 Complet",IF(H16>0.7,"🟡 Avancé",IF(H16>0,"🟠 En cours","⬜ À faire")))
A17: Carrières | B17: =COUNTA('CAR'!A:A)-2 | C17: =COUNTIF('CAR'!I:I,"✅ Passé") | D17: =COUNTIF('CAR'!I:I,"❌ Échoué") | E17: =COUNTIF('CAR'!I:I,"⚠️ Bloqué") | F17: =COUNTIF('CAR'!I:I,"▶️ En cours") | G17: =B17-SUM(C17:F17) | H17: =IF(B17=0,0,C17/B17) | I17: =IF(H17=1,"🟢 Complet",IF(H17>0.7,"🟡 Avancé",IF(H17>0,"🟠 En cours","⬜ À faire")))
A18: CNPS & DISA | B18: =COUNTA('CNP'!A:A)-2 | C18: =COUNTIF('CNP'!I:I,"✅ Passé") | D18: =COUNTIF('CNP'!I:I,"❌ Échoué") | E18: =COUNTIF('CNP'!I:I,"⚠️ Bloqué") | F18: =COUNTIF('CNP'!I:I,"▶️ En cours") | G18: =B18-SUM(C18:F18) | H18: =IF(B18=0,0,C18/B18) | I18: =IF(H18=1,"🟢 Complet",IF(H18>0.7,"🟡 Avancé",IF(H18>0,"🟠 En cours","⬜ À faire")))
A19: Mobile Money & virements | B19: =COUNTA('MM'!A:A)-2 | C19: =COUNTIF('MM'!I:I,"✅ Passé") | D19: =COUNTIF('MM'!I:I,"❌ Échoué") | E19: =COUNTIF('MM'!I:I,"⚠️ Bloqué") | F19: =COUNTIF('MM'!I:I,"▶️ En cours") | G19: =B19-SUM(C19:F19) | H19: =IF(B19=0,0,C19/B19) | I19: =IF(H19=1,"🟢 Complet",IF(H19>0.7,"🟡 Avancé",IF(H19>0,"🟠 En cours","⬜ À faire")))
A20: Assistant IA | B20: =COUNTA('AI'!A:A)-2 | C20: =COUNTIF('AI'!I:I,"✅ Passé") | D20: =COUNTIF('AI'!I:I,"❌ Échoué") | E20: =COUNTIF('AI'!I:I,"⚠️ Bloqué") | F20: =COUNTIF('AI'!I:I,"▶️ En cours") | G20: =B20-SUM(C20:F20) | H20: =IF(B20=0,0,C20/B20) | I20: =IF(H20=1,"🟢 Complet",IF(H20>0.7,"🟡 Avancé",IF(H20>0,"🟠 En cours","⬜ À faire")))
A21: Reporting & Vue DG | B21: =COUNTA('REP'!A:A)-2 | C21: =COUNTIF('REP'!I:I,"✅ Passé") | D21: =COUNTIF('REP'!I:I,"❌ Échoué") | E21: =COUNTIF('REP'!I:I,"⚠️ Bloqué") | F21: =COUNTIF('REP'!I:I,"▶️ En cours") | G21: =B21-SUM(C21:F21) | H21: =IF(B21=0,0,C21/B21) | I21: =IF(H21=1,"🟢 Complet",IF(H21>0.7,"🟡 Avancé",IF(H21>0,"🟠 En cours","⬜ À faire")))
A22: Paramètres | B22: =COUNTA('SET'!A:A)-2 | C22: =COUNTIF('SET'!I:I,"✅ Passé") | D22: =COUNTIF('SET'!I:I,"❌ Échoué") | E22: =COUNTIF('SET'!I:I,"⚠️ Bloqué") | F22: =COUNTIF('SET'!I:I,"▶️ En cours") | G22: =B22-SUM(C22:F22) | H22: =IF(B22=0,0,C22/B22) | I22: =IF(H22=1,"🟢 Complet",IF(H22>0.7,"🟡 Avancé",IF(H22>0,"🟠 En cours","⬜ À faire")))
A23: RBAC | B23: =COUNTA('RBA'!A:A)-2 | C23: =COUNTIF('RBA'!I:I,"✅ Passé") | D23: =COUNTIF('RBA'!I:I,"❌ Échoué") | E23: =COUNTIF('RBA'!I:I,"⚠️ Bloqué") | F23: =COUNTIF('RBA'!I:I,"▶️ En cours") | G23: =B23-SUM(C23:F23) | H23: =IF(B23=0,0,C23/B23) | I23: =IF(H23=1,"🟢 Complet",IF(H23>0.7,"🟡 Avancé",IF(H23>0,"🟠 En cours","⬜ À faire")))
A24: Espace Employé | B24: =COUNTA('ESP'!A:A)-2 | C24: =COUNTIF('ESP'!I:I,"✅ Passé") | D24: =COUNTIF('ESP'!I:I,"❌ Échoué") | E24: =COUNTIF('ESP'!I:I,"⚠️ Bloqué") | F24: =COUNTIF('ESP'!I:I,"▶️ En cours") | G24: =B24-SUM(C24:F24) | H24: =IF(B24=0,0,C24/B24) | I24: =IF(H24=1,"🟢 Complet",IF(H24>0.7,"🟡 Avancé",IF(H24>0,"🟠 En cours","⬜ À faire")))
A25: Workflows & validations | B25: =COUNTA('WF'!A:A)-2 | C25: =COUNTIF('WF'!I:I,"✅ Passé") | D25: =COUNTIF('WF'!I:I,"❌ Échoué") | E25: =COUNTIF('WF'!I:I,"⚠️ Bloqué") | F25: =COUNTIF('WF'!I:I,"▶️ En cours") | G25: =B25-SUM(C25:F25) | H25: =IF(B25=0,0,C25/B25) | I25: =IF(H25=1,"🟢 Complet",IF(H25>0.7,"🟡 Avancé",IF(H25>0,"🟠 En cours","⬜ À faire")))
A26: Temps & pointage | B26: =COUNTA('TPS'!A:A)-2 | C26: =COUNTIF('TPS'!I:I,"✅ Passé") | D26: =COUNTIF('TPS'!I:I,"❌ Échoué") | E26: =COUNTIF('TPS'!I:I,"⚠️ Bloqué") | F26: =COUNTIF('TPS'!I:I,"▶️ En cours") | G26: =B26-SUM(C26:F26) | H26: =IF(B26=0,0,C26/B26) | I26: =IF(H26=1,"🟢 Complet",IF(H26>0.7,"🟡 Avancé",IF(H26>0,"🟠 En cours","⬜ À faire")))
A27: Talents & organisation | B27: =COUNTA('TAL'!A:A)-2 | C27: =COUNTIF('TAL'!I:I,"✅ Passé") | D27: =COUNTIF('TAL'!I:I,"❌ Échoué") | E27: =COUNTIF('TAL'!I:I,"⚠️ Bloqué") | F27: =COUNTIF('TAL'!I:I,"▶️ En cours") | G27: =B27-SUM(C27:F27) | H27: =IF(B27=0,0,C27/B27) | I27: =IF(H27=1,"🟢 Complet",IF(H27>0.7,"🟡 Avancé",IF(H27>0,"🟠 En cours","⬜ À faire")))
A28: Onboarding / Offboarding | B28: =COUNTA('OFF'!A:A)-2 | C28: =COUNTIF('OFF'!I:I,"✅ Passé") | D28: =COUNTIF('OFF'!I:I,"❌ Échoué") | E28: =COUNTIF('OFF'!I:I,"⚠️ Bloqué") | F28: =COUNTIF('OFF'!I:I,"▶️ En cours") | G28: =B28-SUM(C28:F28) | H28: =IF(B28=0,0,C28/B28) | I28: =IF(H28=1,"🟢 Complet",IF(H28>0.7,"🟡 Avancé",IF(H28>0,"🟠 En cours","⬜ À faire")))
A29: Intégrations & sécurité | B29: =COUNTA('INT'!A:A)-2 | C29: =COUNTIF('INT'!I:I,"✅ Passé") | D29: =COUNTIF('INT'!I:I,"❌ Échoué") | E29: =COUNTIF('INT'!I:I,"⚠️ Bloqué") | F29: =COUNTIF('INT'!I:I,"▶️ En cours") | G29: =B29-SUM(C29:F29) | H29: =IF(B29=0,0,C29/B29) | I29: =IF(H29=1,"🟢 Complet",IF(H29>0.7,"🟡 Avancé",IF(H29>0,"🟠 En cours","⬜ À faire")))
A30: Configuration tenant | B30: =COUNTA('CFG'!A:A)-2 | C30: =COUNTIF('CFG'!I:I,"✅ Passé") | D30: =COUNTIF('CFG'!I:I,"❌ Échoué") | E30: =COUNTIF('CFG'!I:I,"⚠️ Bloqué") | F30: =COUNTIF('CFG'!I:I,"▶️ En cours") | G30: =B30-SUM(C30:F30) | H30: =IF(B30=0,0,C30/B30) | I30: =IF(H30=1,"🟢 Complet",IF(H30>0.7,"🟡 Avancé",IF(H30>0,"🟠 En cours","⬜ À faire")))
A31: Cabinet de recrutement | B31: =COUNTA('CAB'!A:A)-2 | C31: =COUNTIF('CAB'!I:I,"✅ Passé") | D31: =COUNTIF('CAB'!I:I,"❌ Échoué") | E31: =COUNTIF('CAB'!I:I,"⚠️ Bloqué") | F31: =COUNTIF('CAB'!I:I,"▶️ En cours") | G31: =B31-SUM(C31:F31) | H31: =IF(B31=0,0,C31/B31) | I31: =IF(H31=1,"🟢 Complet",IF(H31>0.7,"🟡 Avancé",IF(H31>0,"🟠 En cours","⬜ À faire")))
A32: End-to-End | B32: =COUNTA('E2E'!A:A)-2 | C32: =COUNTIF('E2E'!I:I,"✅ Passé") | D32: =COUNTIF('E2E'!I:I,"❌ Échoué") | E32: =COUNTIF('E2E'!I:I,"⚠️ Bloqué") | F32: =COUNTIF('E2E'!I:I,"▶️ En cours") | G32: =B32-SUM(C32:F32) | H32: =IF(B32=0,0,C32/B32) | I32: =IF(H32=1,"🟢 Complet",IF(H32>0.7,"🟡 Avancé",IF(H32>0,"🟠 En cours","⬜ À faire")))
A33: TOTAL GLOBAL | B33: =SUM(B7:B32) | C33: =SUM(C7:C32) | D33: =SUM(D7:D32) | E33: =SUM(E7:E32) | F33: =SUM(F7:F32) | G33: =SUM(G7:G32) | H33: =IF(B33=0,0,C33/B33)
A34: « ⬜ Non exécuté » = Total − (Passé + Échoué + Bloqué + En cours) : inclut les scénarios au statut vide.
A36: INDICATEURS CLÉS EN TEMPS RÉEL
A37: Total scénarios | B37: ✅ Passés | C37: ❌ Échoués | D37: ⚠️ Bloqués | E37: ▶️ En cours | F37: ⬜ Non exécutés | G37: % Réussite | H37: Couverture
A38: =B33 | B38: =C33 | C38: =D33 | D38: =E33 | E38: =F33 | F38: =G33 | G38: =H33 | H38: =IF(B33=0,"0%",TEXT(1-G33/B33,"0%"))

Sheet GUIDE
A1: MODE D'EMPLOI — NexusRH CI Cahier de Recettes
A3: STATUTS DE TEST
A4: Statut | B4: Signification | C4: Couleur
A5: ✅ Passé | B5: Test exécuté et résultat conforme | C5: Vert
A6: ❌ Échoué | B6: Résultat non conforme — bug identifié | C6: Rouge
A7: ⚠️ Bloqué | B7: Test non exécutable (dépendance manquante) | C7: Jaune
A8: ▶️ En cours | B8: Test en cours d'exécution | C8: Bleu
A9: ⬜ Non exécuté | B9: Test planifié, pas encore démarré | C9: Gris
A11: PRIORITÉS
A12: P1 — Critique | B12: Fonctionnalité bloquante, doit passer avant release | C12: Rouge foncé
A13: P2 — Haute | B13: Fonctionnalité importante, impact élevé si KO | C13: Amber
A14: P3 — Moyenne | B14: Fonctionnalité utile, contournement possible | C14: Bleu
A15: P4 — Basse | B15: Amélioration ou cas limite | C15: Vert
A17: REQUALIFICATION EN TICKET
A18: Colonne 'Ticket / Requalification' | B18: Saisir le numéro de ticket (ex: NRH-123)
A19: Commentaire / Amélioration | B19: Détailler le comportement observé et suggestion
A21: WORKFLOW DE TEST
A22: 1. Sélectionner le module (onglet) | B22: Chaque onglet = un module fonctionnel
A23: 2. Exécuter chaque scénario | B23: Suivre les étapes détaillées
A24: 3. Mettre à jour le Statut (colonne I) | B24: Dropdown avec les 5 statuts
A25: 4. Saisir Résultat obtenu (colonne H) | B25: Comportement réel observé
A26: 5. Créer un ticket si Échoué/Bloqué | B26: Saisir référence dans colonne M
A27: 6. Le DASHBOARD se met à jour automatiquement | B27: Formules COUNTIF dynamiques
A29: COMPTES DE TEST
A30: superadmin@nexusrh-ci.com / SuperAdmin1234! | B30: Super Admin Plateforme → /platform/dashboard
A31: admin@sotra.ci / Admin1234! | B31: Admin SOTRA → /dashboard (thème orange)
A32: rh@sotra.ci / Admin1234! | B32: RH Manager SOTRA → /dashboard
A33: manager@sotra.ci / Admin1234! | B33: Manager SOTRA → /dashboard équipe
A34: employe@sotra.ci / Admin1234! | B34: Employé SOTRA → /mon-espace
A35: admin@cabinet-expertise.ci / Admin1234! | B35: Admin Cabinet Expertise CI → /dashboard
A36: employe2@cabinet-expertise.ci / Admin1234! | B36: Employé Cabinet → /mon-espace
A37: coulwao@gmail.com / Openlab2025! | B37: Admin OpenLab Consulting → /dashboard
A39: URL PRODUCTION
A40: https://nexusrh.openlabconsulting.com | B40: Application web NexusRH CI
A41: https://nexusrh.openlabconsulting.com/api/docs | B41: Swagger API (debug)
A43: COMPTES DE TEST COMPLÉMENTAIRES (SOTRA)
A44: chef.perso@sotra.ci | B44: Chargé RH (hr_officer) « Chef Personnel » — mot de passe démo identique à rh@sotra.ci
A45: dg@sotra.ci | B45: Directeur Général (rôle dg, Vue 360° — module dg_view à activer)
A46: Compte raf_site / readonly | B46: À créer dans Paramètres → Utilisateurs si nécessaire (scénarios RBA / PAY multi-filiales)
A48: CAMPAGNE 10/2026 — NOUVEAUX ONGLETS
...

Sheet AUTH
A1: AUTHENTIFICATION & SÉCURITÉ · 29 scénarios
A2: ID Test | B2: Priorité | C2: Titre du scénario | D2: Description / Contexte | E2: Prérequis / Données | F2: Étapes détaillées | G2: Résultat attendu | H2: Résultat obtenu | I2: Statut | J2: Testeur | K2: Date test | L2: Durée (min) | M2: Ticket / Requalification | N2: Commentaire / Amélioration | O2: Sprint | P2: Env.
A3: AUTH-001 | B3: P1 — Critique | C3: Login super_admin valide | D3: Connexion avec superadmin@nexusrh-ci.com / SuperAdmin1234! | E3: API déployée, DB seedée | F3: 1. Ouvrir nexusrh.openlabconsulting.com 2. Saisir email + mdp 3. Cliquer Connexion | G3: Token JWT reçu, redirection vers /platform/dashboard, sidebar plateforme affichée | H3: HTTP 200, JWT role=super_admin / schema=platform, redirectTo=/platform/dashboard ; sidebar plateforme (PlatformLayout sous PlatformGuard). Verifie en live prod. | I3: ✅ Passé | J3: Agents IA (live prod + code) | K3: 23/06/2026 | O3: Sprint 1 | P3: Production
A4: AUTH-002 | B4: P1 — Critique | C4: Login admin tenant valide | D4: Connexion admin@sotra.ci / Admin1234! | E4: Tenant SOTRA seedé | F4: 1. Saisir admin@sotra.ci 2. Saisir Admin1234! 3. Cliquer Connexion | G4: Redirection /dashboard, thème orange SOTRA appliqué, sidebar RH complète | H4: HTTP 200, JWT role=admin / schema=tenant_sotra ; tenantConfig orange primaryColor #E85D04 applique au login (authStore), redirect /dashboard + sidebar RH complete. NB: changement de mot de passe force au 1er login (post-reset demo). | I4: ✅ Passé | J4: Agents IA (live prod + code) | K4: 23/06/2026 | O4: Sprint 1 | P4: Production
A5: AUTH-003 | B5: P1 — Critique | C5: Login mot de passe incorrect → message d'erreur visible | D5: Vérifier que le message 401 remonte au formulaire (plus de rechargement silencieux) | E5: Correctif intercepteur 401 déployé | F5: 1. Saisir un email valide 2. Saisir un mauvais mot de passe 3. Soumettre | G5: Message 'Email ou mot de passe incorrect' affiché dans le formulaire, pas de rechargement de page | H5: 401 'Email ou mot de passe incorrect' ; intercepteur axios exclut /auth/* donc message affiche dans le formulaire sans rechargement (message UI generique anti-enumeration OWASP A07). | I5: ✅ Passé | J5: Agents IA (live prod + code) | K5: 23/06/2026 | O5: Sprint 1 | P5: Production
A6: AUTH-004 | B6: P2 — Haute | C6: Login email inexistant | D6: Email qui n'existe dans aucun tenant | F6: 1. Saisir email@inconnu.com 2. Mdp quelconque 3. Soumettre | G6: Message d'erreur 401 affiché sans plantage | H6: Email inexistant donne 401 message generique identique au mauvais mot de passe (anti-enumeration ; bcrypt dummy temps constant) ; corps malforme donne 400 propre, aucun 500. | I6: ✅ Passé | J6: Agents IA (live prod + code) | K6: 23/06/2026 | O6: Sprint 1 | P6: Production
A7: AUTH-005 | B7: P1 — Critique | C7: Redirection rôle employee → /mon-espace | D7: employe@sotra.ci doit atterrir sur son espace | E7: Seed SOTRA OK | F7: 1. Connecter employe@sotra.ci 2. Observar la redirection | G7: Redirection automatique vers /mon-espace, sidebar réduite (5 items seulement) | H7: HTTP 200, JWT role=employee / schema=tenant_sotra ; redirect /mon-espace + sidebar self-service reduite dediee (10 items, tous /mon-espace) ; RoleGuard bloque /employees, /payroll, /reporting. | I7: ✅ Passé | J7: Agents IA (live prod + code) | K7: 23/06/2026 | O7: Sprint 1 | P7: Production
A8: AUTH-006 | B8: P1 — Critique | C8: Redirection rôle manager → /dashboard | D8: manager@sotra.ci → /dashboard version manager | F8: 1. Connecter manager@sotra.ci 2. Observer dashboard | G8: Dashboard manager affiché (équipe, demandes à valider), pas les KPIs admin | H8: HTTP 200, JWT role=manager/tenant_sotra ; redirect /dashboard qui rend la variante ManagerDashboard (mon equipe + demandes a valider), sans KPIs admin (requete /payroll desactivee). | I8: ✅ Passé | J8: Agents IA (live prod + code) | K8: 23/06/2026 | O8: Sprint 1 | P8: Production
A9: AUTH-007 | B9: P1 — Critique | C9: Redirection super_admin → /platform/dashboard | D9: Aucun accès aux données RH | F9: 1. Connecter superadmin@nexusrh-ci.com 2. Tenter /dashboard | G9: Redirigé vers /platform/dashboard, sidebar plateforme uniquement | H9: CORRIGE: la route /dashboard n'avait aucune garde -> super_admin pouvait y acceder (coquille vide, aucune fuite car API 403). Ajout RhDashboardGuard (super_admin -> /platform/dashboard, employee -> /mon-espace). Verifie code + typecheck. | I9: ✅ Passé | J9: Agents IA + correctif | K9: 23/06/2026 | O9: Sprint 1 | P9: Production
A10: AUTH-008 | B10: P2 — Haute | C10: Refresh automatique token JWT expiré | D10: Le refresh token permet de renouveler le JWT sans déconnexion | E10: Token expiré simulé | F10: 1. Connecter 2. Attendre expiration JWT ou modifier exp dans DevTools 3. Effectuer une requête API | G10: Token rafraîchi silencieusement, requête relancée, utilisateur non déconnecté | H10: CORRIGE + CONFIRME LIVE: flux refresh token rotatif (login -> refreshToken 64 hex ; POST /auth/refresh-token -> nouveau JWT valide + nouveau refreshToken, ancien revoque=401). REGRESSION detectee a AUTH-015 et corrigee: ne plus emettre de refresh token si pwdResetRequired/mfaPending (sinon contournement du garde) + re-verif expiration au refresh. | I10: ✅ Passé | J10: Agents IA + correctif | K10: 23/06/2026 | O10: Sprint 1 | P10: Production
A11: AUTH-009 | B11: P2 — Haute | C11: Déconnexion propre | D11: Store Zustand vidé, redirection /login | E11: Session active | F11: 1. Cliquer sur Déconnexion 2. Vérifier localStorage/sessionStorage | G11: Token supprimé, store authStore vidé, redirection /login, route protégée inaccessible | H11: Deconnexion vide entierement authStore (token/user/tenantConfig/refreshToken), supprime la cle localStorage nexusrhci-auth, purge le cache React Query, guards reactifs -> /login. | I11: ✅ Passé | J11: Agents IA (live prod + code) | K11: 23/06/2026 | O11: Sprint 1 | P11: Production
A12: AUTH-010 | B12: P1 — Critique | C12: Route protégée sans token → /login | D12: Un utilisateur non connecté tente d'accéder /dashboard | F12: 1. Sans session, accéder directement à /dashboard | G12: Redirection automatique vers /login | H12: Sans token, AuthGuard redirige /dashboard (et toute route protegee) vers /login via Navigate replace ; aucune route protegee accessible sans session ; pas de page blanche. | I12: ✅ Passé | J12: Agents IA (live prod + code) | K12: 23/06/2026 | O12: Sprint 1 | P12: Production
A13: AUTH-011 | B13: P2 — Haute | C13: must_change_password = false après seed | D13: Les comptes seedés n'exigent pas de changement de mdp | E13: Seed v2 avec last_login_at déployé | F13: 1. Connecter n'importe quel compte seedé | G13: Connexion directe au dashboard, pas de popup changement de mot de passe | H13: COMPORTEMENT ATTENDU (decision recette): le controle HIBP force le changement quand le mdp est compromis (Admin1234! dans HIBP) -> bonne pratique securite. La logique last_login_at est correcte. Scenario a reformuler (le critere 'must_change_password=false' suppose un mdp non compromis). | I13: ✅ Passé | J13: Agents IA (live prod + code) | K13: 23/06/2026 | O13: Sprint 1 | P13: Production
A14: AUTH-012 | B14: P3 — Moyenne | C14: Activation MFA (QR code TOTP) | D14: L'utilisateur active la double authentification | F14: 1. Mon profil → Sécurité → Activer MFA 2. Scanner QR code avec app TOTP 3. Valider avec code | G14: MFA activé, codes de secours affichés, connexion suivante demande OTP | H14: Code MFA TOTP conforme: secret + QR (data URL) + 10 backup codes hashes bcrypt12 ; mfa_enabled active seulement apres validation d'un code ; login d'un compte mfa_enabled renvoie un challenge 202. Parcours scan-QR / saisie-OTP a valider manuellement en UI. | I14: ⚠️ Bloqué | J14: Agents IA (live prod + code) | K14: 23/06/2026 | O14: Sprint 1 | P14: Production
A15: AUTH-013 | B15: P2 — Haute | C15: MFA code OTP valide | D15: Connexion avec MFA activé | E15: MFA activé sur le compte | F15: 1. Connecter 2. Saisir code TOTP valide | G15: Accès accordé, token JWT émis | H15: Flux TOTP->JWT conforme: login mfa_enabled -> 202 challenge (sans JWT), /auth/mfa/login-verify valide via otplib (fenetre +-1 step) + anti-rejeu Redis (consumeTotpStep) + backup codes consommes 1x, puis emet le JWT final. Non testable live (aucun compte MFA seede). | I15: ⚠️ Bloqué | J15: Agents IA (live prod + code) | K15: 23/06/2026 | O15: Sprint 1 | P15: Production
A16: AUTH-014 | B16: P2 — Haute | C16: MFA code OTP invalide → rejet | E16: MFA activé | F16: 1. Connecter 2. Saisir code TOTP périmé ou incorrect | G16: Erreur 401, message explicite, pas de token émis | H16: Code TOTP invalide -> 401 'Code MFA invalide', AUCUN token emis (garde avant jwt.sign) ; anti-rejeu (step deja consomme refuse) ; rate-limit 10/15min ; challenge expire -> 401 ; body malforme -> 400 (Zod strict), aucun 500. | I16: ✅ Passé | J16: Agents IA (live prod + code) | K16: 23/06/2026 | O16: Sprint 1 | P16: Production
A17: AUTH-015 | B17: P1 — Critique | C17: Isolation multi-tenant | D17: Token SOTRA ne donne pas accès aux données Cabinet Expertise CI | E17: 2 tenants seedés | F17: 1. Connecter admin@sotra.ci 2. Inspecter les requêtes API 3. Tenter d'appeler /api/employees avec schéma cabinet | G17: 403 Forbidden ou données vides, jamais de fuite cross-tenant | H17: Isolation parfaite: le schema tenant est derive UNIQUEMENT du JWT signe (request.user.schemaName), tentative d'override par header X-Schema/?schema ignoree (renvoie toujours SOTRA) ; donnees SOTRA vs Cabinet disjointes (/auth/me tenantId differents) ; zero fuite cross-tenant. | I17: ✅ Passé | J17: Agents IA (live prod + code) | K17: 23/06/2026 | O17: Sprint 1 | P17: Production
A18: AUTH-016 | B18: P1 — Critique | C18: [NON-REGRESSION] Seed DO UPDATE password_hash | D18: Régression résolue 2026-05-15 : seed ON CONFLICT DO NOTHING ne rafraîchissait pas les hashes SOTRA/Cabinet (login 401 sur tous les comptes) | E18: Re-seed exécuté en prod | F18: 1. kubectl apply seed-job-prod.yaml ou pnpm run db:seed 2. Tenter login admin@sotra.ci / Admin1234! | G18: Login OK 200 — le seed met à jour password_hash si l'utilisateur existe déjà | H18: Login admin@sotra.ci 200 apres re-seed du deploiement ; le seed fait ON CONFLICT (email) DO UPDATE SET password_hash pour les users tenant (rafraichit le hash, anti-regression DO NOTHING). super_admin reste DO NOTHING = choix delibere documente. | I18: ✅ Passé | J18: Agents IA (live prod + code) | K18: 23/06/2026 | O18: Sprint 1 | P18: Production
A19: AUTH-017 | B19: P1 — Critique | C19: [NON-REGRESSION] Script reset-admin-passwords.sql | D19: Récupération prod sans rebuild — applique 8 UPDATE bcrypt 12 rounds | E19: Accès kubectl prod | F19: 1. kubectl exec -i postgres-0 -- psql -U nexusrh -d nexusrh < scripts/reset-admin-passwords.sql 2. Vérifier les is_active=true 3. Login admin@sotra.ci | G19: 8 lignes UPDATE OK, login fonctionnel sur les 8 comptes documentés | H19: CORRIGE: le script scripts/reset-admin-passwords.sql ne mettait pas password_changed_at=now() -> ne levait pas l'expiration mdp (le .ts canonique le faisait). Ajoute password_changed_at=now() aux 8 UPDATE. 8 UPDATE (= attendu) + is_active=true + login admin@sotra.ci 200. | I19: ✅ Passé | J19: Agents IA + correctif | K19: 23/06/2026 | O19: Sprint 1 | P19: Production
A20: AUTH-018 | B20: P2 — Haute | C20: [NON-REGRESSION] Script reset-admin-passwords.ts standalone | D20: pnpm run admin:reset-passwords:dry-run puis admin:reset-passwords | E20: DB locale ou prod accessible | F20: 1. pnpm --filter @nexusrhci/api run admin:reset-passwords:dry-run 2. Vérifier la liste des comptes ciblés 3. Lancer admin:reset-passwords | G20: Mode dry-run liste les 8 cibles. Lancement réel : ✓ pour chaque compte. Bcrypt 12 rounds, OWASP A02 respecté | H20: Dry-run liste 17 cibles sans ecrire ; bcrypt 12 rounds (OWASP A02) ; SET is_active=true + password_changed_at=now() ; comptes reels (super_admin, OpenLab) proteges sauf RESET_REAL_ACCOUNTS=true ; double garde FORCE_RESET_PROD requise en prod. | I20: ✅ Passé | J20: Agents IA (live prod + code) | K20: 23/06/2026 | O20: Sprint 1 | P20: Production
A21: AUTH-019 | B21: P1 — Critique | C21: Mot de passe oublié — demande de lien | D21: Flux « Mot de passe oublié » depuis /login (POST /auth/forgot-password). | E21: Compte employe@sotra.ci actif, SMTP tenant ou plateforme opérationnel | F21: 1. /login → « Mot de passe oublié ? » 2. Saisir employe@sotra.ci → Envoyer 3. Répéter avec un email inexistant (inconnu@sotra.ci) | G21: Même message neutre dans les 2 cas (pas d'énumération) ; email reçu pour le compte existant avec lien /reset-password à jeton à durée limitée | O21: Recette 10/2026 | P21: Production
A22: AUTH-020 | B22: P1 — Critique | C22: Réinitialisation du mot de passe via le lien | D22: POST /auth/reset-password avec jeton reçu par email. | E22: Lien de réinitialisation reçu (scénario précédent) | F22: 1. Ouvrir le lien /reset-password?token=… 2. Saisir un mot de passe conforme à la politique 3. Se connecter avec le nouveau mot de passe 4. Réutiliser le même lien une 2e fois | G22: Mot de passe changé, login OK ; le jeton est à usage unique (2e usage refusé avec message clair) ; jeton expiré refusé | O22: Recette 10/2026 | P22: Production
A23: AUTH-021 | B23: P1 — Critique | C23: Verrouillage du compte après N échecs | D23: Verrouillage paramétrable (account-lockout) câblé au login. | E23: Seuil configuré dans Plateforme → Paramètres (ex. 5 tentatives) | F23: 1. Se tromper 5 fois de mot de passe sur chef.perso@sotra.ci 2. Tenter avec le bon mot de passe 3. Attendre la durée de verrouillage puis réessayer | G23: Après le seuil : message « compte temporairement verrouillé » même avec le bon mot de passe ; déverrouillage automatique après la durée ; tentative auditée | O23: Recette 10/2026 | P23: Production
A24: AUTH-022 | B24: P1 — Critique | C24: Politique mot de passe — expiration (30 j) | D24: passwordMaxAgeDays de la politique de sécurité plateforme. | E24: Compte de test dont le mot de passe a plus de 30 jours (ou durée abaissée à 1 j par le super_admin) | F24: 1. Se connecter avec le compte expiré 2. Suivre l'écran de changement obligatoire 3. Saisir un nouveau mot de passe | G24: Connexion bloquée tant que le mot de passe n'est pas changé ; après changement, accès normal ; 0 = jamais d'expiration | O24: Recette 10/2026 | P24: Production
A25: AUTH-023 | B25: P2 — Haute | C25: Politique mot de passe — anti-réutilisation (historique) | D25: Historique des N derniers mots de passe (défaut 5). | E25: Compte employe@sotra.ci | F25: 1. Mon profil → Changer le mot de passe 2. Saisir comme nouveau mot de passe l'un des 5 précédents | G25: Refus explicite « mot de passe déjà utilisé récemment » ; un mot de passe jamais utilisé est accepté | O25: Recette 10/2026 | P25: Production
A26: AUTH-024 | B26: P2 — Haute | C26: Politique mot de passe — mot de passe compromis (HaveIBeenPwned) | D26: Vérification k-anonymat, non bloquante si pas d'accès internet. | E26: Vérification de fuite activée (défaut) | F26: 1. Changer son mot de passe en « Password123! » 2. Changer ensuite pour un mot de passe robuste unique | G26: 1er refusé (mot de passe présent dans des fuites) ; 2e accepté ; le mot de passe en clair n'est jamais transmis (seul le préfixe SHA-1) | O26: Recette 10/2026 | P26: Production
A27: AUTH-025 | B27: P1 — Critique | C27: MFA obligatoire — enrôlement forcé au 1er login | D27: MFA rendu obligatoire par le super_admin (super_admin / employés tenant) → /mfa-setup. | E27: Politique « MFA obligatoire tenant » activée ; compte sans MFA | F27: 1. Se connecter avec rh@sotra.ci 2. Constater la redirection /mfa-setup 3. Scanner le QR code, saisir le code TOTP | G27: Accès à l'application impossible avant enrôlement ; après validation du code, accès normal ; login suivant demande le code | O27: Recette 10/2026 | P27: Production
A28: AUTH-026 | B28: P2 — Haute | C28: MFA — anti-rejeu du code TOTP | D28: Un code TOTP déjà utilisé ne peut pas être réutilisé. | E28: Compte avec MFA actif | F28: 1. Se connecter avec un code TOTP valide 2. Se déconnecter puis se reconnecter immédiatement avec le MÊME code | G28: 2e utilisation du même code refusée (401 « Code MFA invalide ») | O28: Recette 10/2026 | P28: Production
A29: AUTH-027 | B29: P2 — Haute | C29: Réinitialisation MFA d'un utilisateur par l'admin | D29: POST /settings/users/:id/reset-mfa. | E29: admin@sotra.ci ; utilisateur avec MFA actif ayant perdu son téléphone | F29: 1. Paramètres → Utilisateurs → utilisateur → Réinitialiser MFA 2. L'utilisateur se reconnecte | G29: MFA désactivé pour cet utilisateur, nouvel enrôlement demandé si MFA obligatoire ; action auditée | O29: Recette 10/2026 | P29: Production
A30: AUTH-028 | B30: P1 — Critique | C30: Déconnexion — révocation du jeton (jti) | D30: Le refresh/access token révoqué à la déconnexion ne doit plus fonctionner. | E30: Session rh@sotra.ci ouverte, jeton copié (outil dev) | F30: 1. Copier l'access token 2. Se déconnecter 3. Rejouer un appel API (GET /employees) avec l'ancien jeton et un refresh avec l'ancien refresh token | G30: 401 dans les deux cas : jeton révoqué côté serveur | O30: Recette 10/2026 | P30: Production
A31: AUTH-029 | B31: P2 — Haute | C31: Mise hors ligne tenant — message au login | D31: Tenant mis hors ligne par le super_admin avec message personnalisé. | E31: Tenant de test mis hors ligne (voir PLT) | F31: 1. Se connecter avec un compte du tenant hors ligne, mauvais mot de passe 2. Puis bon mot de passe | G31: Mauvais mdp → message d'échec générique (pas de fuite) ; bon mdp → message hors ligne personnalisé, aucun accès ; API renvoie 403 même avec un jeton existant | O31: Recette 10/2026 | P31: Production

Sheet PLT
A1: PORTAIL SUPER ADMIN · 39 scénarios
A2: ID Test | B2: Priorité | C2: Titre du scénario | D2: Description / Contexte | E2: Prérequis / Données | F2: Étapes détaillées | G2: Résultat attendu | H2: Résultat obtenu | I2: Statut | J2: Testeur | K2: Date test | L2: Durée (min) | M2: Ticket / Requalification | N2: Commentaire / Amélioration | O2: Sprint | P2: Env.
A3: PLT-001 | B3: P1 — Critique | C3: KPIs plateforme corrects | D3: Dashboard /platform/dashboard affiche tenants actifs, trials, MRR | E3: 2+ tenants seedés | F3: 1. Connecter superadmin 2. Observer KPI cards | G3: Valeurs cohérentes avec la base (ex: 3 tenants actifs = 3 affiché) | H3: KPIs dashboard plateforme {actifs, trial, suspendus, total} parfaitement coherents avec la liste reelle des tenants recomptee par statut. Issus d'une vraie requete count(*) FILTER (status=...) sur platform.tenants, aucune valeur en dur. | I3: ✅ Passé | J3: Agents IA + live (super_admin) | K3: 23/06/2026 | O3: Sprint 1 | P3: Production
A4: PLT-002 | B4: P1 — Critique | C4: Création tenant — wizard 3 étapes | D4: Créer un nouveau tenant via le formulaire | E4: Super admin connecté | F4: 1. /platform/tenants/new 2. Étape 1: nom, slug, plan, secteur, ville 3. Étape 2: admin email/prénom/nom 4. Étape 3: couleurs | G4: Tenant créé, schema PostgreSQL provisionné, email admin envoyé, tempPassword affiché | H4: POST /platform/tenants -> 201, data {id, slug, schemaName=tenant_<slug>, planType} + tempPassword (12c) + adminEmail ; schema PG provisionne (toutes les tables creees, GET /tenants/{id}=200) ; max_users/max_employees selon plan ; email admin non bloquant (.catch). | I4: ✅ Passé | J4: Agents IA + live (super_admin) | K4: 23/06/2026 | O4: Sprint 1 | P4: Production
A5: PLT-003 | B5: P2 — Haute | C5: Slug auto-généré depuis le nom | D5: Le slug se pré-remplit en minuscules-sans-espaces | F5: 1. Saisir nom entreprise 'Tech Corp' 2. Observer le champ slug | G5: Slug = 'tech-corp' (minuscules, tirets, sans caractères spéciaux) | H5: CORRIGE: le wizard n'auto-generait PAS le slug depuis le nom (2 champs independants, aucune slugification). Ajout slugify('Tech Corp')->'tech-corp' (minuscules/accents retires/espaces->tirets) sur saisie du nom, slug restant editable + nettoye a la frappe (PlatformTenantNew.tsx). | I5: ✅ Passé | J5: Agents IA + correctif | K5: 23/06/2026 | O5: Sprint 1 | P5: Production
A6: PLT-004 | B6: P2 — Haute | C6: Slug déjà existant → erreur | E6: Tenant 'sotra' existant | F6: 1. Créer un tenant avec slug 'sotra' | G6: Erreur explicite 'Slug déjà utilisé', formulaire non soumis | H6: POST /platform/tenants slug='sotra' (deja pris) -> HTTP 409 'Le slug "sotra" est deja utilise', aucun tenant cree/duplique. TenantSlugConflictError mappee en 409. | I6: ✅ Passé | J6: Agents IA + live (super_admin) | K6: 23/06/2026 | O6: Sprint 1 | P6: Production
A7: PLT-005 | B7: P2 — Haute | C7: Seed données démo (seedDemoData) | D7: Cocher l'option inject démo lors création | F7: 1. Wizard création 2. Cocher 'Injecter données de démonstration' 3. Créer | G7: 8 employés, 3 mois de bulletins créés dans le nouveau tenant, non bloquant | H7: CORRIGE: seedDemoData:true ne produisait AUCUNE donnee (0 employe). Cause: seed-demo.ts desync du schema (gross_salary->base_salary, pay_period_id->period_id, total_employee_contributions->total_cnps_sal, income_tax->its, pay_periods label/year->month). INSERT realignes sur le seed principal + VALIDES en direct (rollback). Provisioning lui-meme complet (toutes tables). Non bloquant OK. | I7: ✅ Passé | J7: Agents IA + correctif | K7: 23/06/2026 | O7: Sprint 1 | P7: Production
A8: PLT-006 | B8: P1 — Critique | C8: tempPassword retourné dans réponse | D8: En cas d'échec email, le mdp reste accessible | F8: 1. Créer un tenant 2. Observer la réponse écran de confirmation | G8: Mot de passe temporaire affiché dans l'encart de succès | H8: Apres creation tenant, l'encart de succes affiche adminEmail + tempPassword (bloc code copiable) ; l'API renvoie tempPassword dans le JSON 201. Confirme en live (PLT-002/005). | I8: ✅ Passé | J8: Agents IA + live (super_admin) | K8: 23/06/2026 | O8: Sprint 1 | P8: Production
A9: PLT-007 | B9: P1 — Critique | C9: Liste tenants paginée | D9: Tableau /platform/tenants | E9: 3+ tenants | F9: 1. Accéder /platform/tenants | G9: Tableau avec nom, plan, ville, statut, nb users, nb employés, actions | H9: CORRIGE: GET /platform/tenants enrichit chaque tenant avec user_count + employee_count REELS (comptes dans son schema) ; colonnes 'Utilisateurs' et 'Employes' (reel/quota) ajoutees a la liste. + pagination existante. | I9: ✅ Passé | J9: Agents IA + correctif | K9: 23/06/2026 | O9: Sprint 1 | P9: Production
A10: PLT-008 | B10: P2 — Haute | C10: Filtrage tenants par statut | D10: Filtre active/trial/suspended | F10: 1. Utiliser le filtre statut | G10: Tableau filtré correctement | H10: CORRIGE: ajout d'un selecteur de statut (Tous/Actifs/Trial/Suspendus) cote UI qui alimente la requete ?status= (le backend filtrait deja, parametre/anti-injection). Le tableau se filtre desormais. | I10: ✅ Passé | J10: Agents IA + correctif | K10: 23/06/2026 | O10: Sprint 1 | P10: Production
A11: PLT-009 | B11: P1 — Critique | C11: Détail tenant — 4 onglets | D11: Apparence, Plan, Modules, Données | F11: 1. Cliquer sur un tenant dans la liste | G11: 4 onglets affichés et fonctionnels | H11: CORRIGE: page detail refondue en 4 ONGLETS (Apparence, Plan, Modules, Donnees). Nouvel onglet Donnees = stats (users/employes/bulletins) + export RGPD (JSON) + suppression definitive (DELETE avec confirmation du slug + DROP schema). 3 endpoints backend ajoutes. | I11: ✅ Passé | J11: Agents IA + correctif | K11: 23/06/2026 | O11: Sprint 1 | P11: Production
A12: PLT-010 | B12: P2 — Haute | C12: Modification apparence — couleur primaire | D12: Changer couleur et observer preview live | F12: 1. Onglet Apparence 2. Changer couleur primaire 3. Observer prévisualisation 4. Sauvegarder | G12: Couleur mise à jour, preview reflète le changement immédiatement | H12: CORRIGE (2 volets): (1) FIX WAF CRITIQUE - CRS 911100 bloquait PATCH/PUT/DELETE -> debloque, PATCH /tenants/:id primary_color persiste (200). (2) onglet Apparence du detail rendu EDITABLE : color pickers primaire/secondaire + previsualisation live + sauvegarde (PATCH). Avant: lecture seule. | I12: ✅ Passé | J12: Agents IA + correctif | K12: 23/06/2026 | O12: Sprint 1 | P12: Production
A13: PLT-011 | B13: P2 — Haute | C13: Modification plan tenant | D13: Changer de trial → business | F13: 1. Onglet Plan 2. Sélectionner Business 3. Sauvegarder | G13: Plan mis à jour dans platform.tenants, maxUsers/maxEmployees ajustés selon PLAN_DEFAULTS | H13: CORRIGE: changer le plan n'ajustait pas les quotas + plan non editable. Le PATCH /tenants/:id reajuste max_users/max_employees selon PLAN_DEFAULTS quand plan_type change ; selecteur de plan ajoute a l'onglet Plan. (Live avant: business gardait 30/30 -> desormais 100/150.) | I13: ✅ Passé | J13: Agents IA + correctif | K13: 23/06/2026 | O13: Sprint 1 | P13: Production
A14: PLT-012 | B14: P2 — Haute | C14: Suspension tenant | D14: Tenant passé en statut suspended | F14: 1. Onglet Plan → Suspendre | G14: Status = suspended, login des users du tenant retourne erreur | H14: Suspension tenant OK (live): POST /suspend -> status=suspended ; login d'un user du tenant renvoie {error:message,offline:true} (bloque). Dialogue de message hors-ligne cote UI. | I14: ✅ Passé | J14: Agents IA + live (super_admin) | K14: 23/06/2026 | O14: Sprint 1 | P14: Production
A15: PLT-013 | B15: P2 — Haute | C15: Réactivation tenant | E15: Tenant suspendu | F15: 1. Onglet Plan → Réactiver | G15: Status = active, users peuvent se reconnecter | H15: Reactivation OK (live): POST /reactivate -> status=active, offline_message=NULL, cache invalide ; le login du user du tenant refonctionne (200). | I15: ✅ Passé | J15: Agents IA + live (super_admin) | K15: 23/06/2026 | O15: Sprint 1 | P15: Production
A16: PLT-014 | B16: P2 — Haute | C16: Consulter utilisateurs tenant | D16: Lecture seule des users d'un tenant | F16: 1. /platform/tenants/:id/users | G16: Liste avec email, rôle, statut, date création — pas de création depuis ici | H16: CORRIGE: aucune consultation des utilisateurs du tenant (endpoint + page absents). Ajout GET /platform/tenants/:id/users (email, role, statut, date - lecture seule) + liste dans l'onglet Donnees (sans creation depuis cette vue). | I16: ✅ Passé | J16: Agents IA + correctif | K16: 23/06/2026 | O16: Sprint 1 | P16: Production
A17: PLT-015 | B17: P2 — Haute | C17: Suspension utilisateur tenant | F17: 1. Trouver un utilisateur 2. Cliquer Suspendre | G17: is_active = false, cet user ne peut plus se connecter | H17: CORRIGE: impossible de suspendre un utilisateur individuel (seul le tenant entier). Ajout PATCH /platform/tenants/:id/users/:userId {isActive} (UPDATE users.is_active dans le schema tenant) + boutons Suspendre/Reactiver ; le blocage login is_active=false existait deja cote auth. | I17: ✅ Passé | J17: Agents IA + correctif | K17: 23/06/2026 | O17: Sprint 1 | P17: Production
A18: PLT-016 | B18: P2 — Haute | C18: Reset admin tenant | D18: Regénérer un mdp temporaire pour l'admin | F18: 1. POST /platform/tenants/:id/reset-admin | G18: Nouveau tempPassword retourné + email envoyé | H18: Live: POST /platform/tenants/:id/reset-admin -> adminEmail + tempPassword (12c) ; bcrypt 12, is_active=true, email non bloquant. Bouton dans l'onglet Plan + affichage tempPassword. | I18: ✅ Passé | J18: Agents IA + live (super_admin) | K18: 23/06/2026 | O18: Sprint 1 | P18: Production
A19: PLT-017 | B19: P3 — Moyenne | C19: Diagnostic admin-status | D19: GET /platform/tenants/:id/admin-status | F19: 1. Appeler l'endpoint via Swagger | G19: JSON avec schemaExists, adminUser.isActive, hasPasswordHash, issue | H19: Live: GET /platform/tenants/:id/admin-status -> {schemaExists:true, tenantName, adminUser:{is_active, has_hash, mfa_enabled}, issue:null}. Diagnostic complet conforme. | I19: ✅ Passé | J19: Agents IA + live (super_admin) | K19: 23/06/2026 | O19: Sprint 1 | P19: Production
A20: PLT-018 | B20: P1 — Critique | C20: Logs activité cross-tenant | D20: /platform/logs | F20: 1. Accéder /platform/logs | G20: Logs triés par date, avec tenant, user, action, IP | H20: CORRIGE: l'audit plateforme etait SILENCIEUSEMENT PERDU (auditLogPlatform ecrivait dans platform.audit_log, table jamais creee, .catch() avalait l'echec) + page /platform/logs inexistante. Ajout table platform.audit_log (migrations, OWASP A09) + GET /logs (jointure entity_id, pagination hasMore) + page PlatformLogs (date/tenant/action/entite/user/IP) + route + sidebar + i18n. | I20: ✅ Passé | J20: Agents IA + correctif | K20: 23/06/2026 | O20: Sprint 1 | P20: Production
A21: PLT-019 | B21: P3 — Moyenne | C21: Alerte trials expirant < 7 jours | D21: Dashboard plateforme signale les essais proches de l'expiration | E21: Tenant trial.endsAt dans < 7j | F21: 1. Observer le panneau alertes du dashboard | G21: Badge rouge avec le nom du tenant et date d'expiration | H21: CORRIGE: aucune alerte de trials expirant. GET /platform/dashboard renvoie desormais expiringTrials (status=trial, trial_ends_at < 7j) ; panneau d'alerte rouge (nom tenant + date expiration) ajoute au dashboard super_admin. | I21: ✅ Passé | J21: Agents IA + correctif | K21: 23/06/2026 | O21: Sprint 1 | P21: Production
A22: PLT-020 | B22: P2 — Haute | C22: Thématisation dynamique au login | D22: Au login, les couleurs tenant s'appliquent | F22: 1. Accéder page login SOTRA 2. Saisir admin@sotra.ci | G22: Bouton login orange (#E85D04), logo SOTRA visible avant même de se connecter | H22: CORRIGE (approche ?tenant=slug, choix recette): endpoint PUBLIC GET /public/brand/by-slug/:slug (couleur+logo+nom, tenant suspendu exclu) ; la page login lit le slug depuis ?tenant= (ou sous-domaine) et applique le theme AVANT login (applyTenantTheme exporte) + affiche le logo/nom du tenant. Bouton a la vraie couleur du tenant (plus par coincidence). | I22: ✅ Passé | J22: Agents IA + correctif | K22: 23/06/2026 | O22: Sprint 1 | P22: Production
A23: PLT-021 | B23: P3 — Moyenne | C23: Graphique croissance tenants 12 mois | D23: LineChart sur le dashboard plateforme | F23: 1. Observer le graphique dashboard plateforme | G23: Courbe affichée avec données des 12 derniers mois | H23: CORRIGE: aucun graphique de croissance (backend ni frontend). GET /platform/dashboard renvoie desormais growth (12 mois glissants, count par mois via generate_series + group by created_at) ; LineChart Recharts ajoute au dashboard plateforme. | I23: ✅ Passé | J23: Agents IA + correctif | K23: 23/06/2026 | O23: Sprint 1 | P23: Production
A24: PLT-022 | B24: P2 — Haute | C24: MRR estimé FCFA | D24: KPI card affiche le revenu mensuel récurrent estimé | F24: 1. Observer KPI dashboard plateforme | G24: Valeur en FCFA calculée selon plan × tarif indicatif | H24: CORRIGE: KPI MRR absent. GET /platform/dashboard calcule estimatedMrr (FCFA) selon tarifs indicatifs par plan (starter 65k, business 10k/employe) sur les tenants ACTIFS uniquement (trial/enterprise/public=0) ; KPI card 'MRR estime' formatee FCFA ajoutee. | I24: ✅ Passé | J24: Agents IA + correctif | K24: 23/06/2026 | O24: Sprint 1 | P24: Production
A25: PLT-023 | B25: P2 — Haute | C25: Feature flags par tenant | D25: Activer/désactiver modules individuellement | F25: 1. Onglet Modules d'un tenant 2. Désactiver 'IA Assistant' 3. Connecter admin du tenant | G25: Module IA n'apparaît pas dans la sidebar du tenant | H25: Backend CONFORME (live): PUT /modules persiste enabled_modules, login renvoie tenantConfig.enabledModules (ai true->false apres desactivation), enforcement API hook /ai -> 403 moduleDisabled. CORRIGE cote UI: le widget IA flottant (AiChat) etait rendu inconditionnellement -> desormais gate par isModuleEnabled(tenantConfig,'ai') dans MainLayout. Cle module = 'ai'. | I25: ✅ Passé | J25: Agents IA + correctif | K25: 23/06/2026 | O25: Sprint 1 | P25: Production
A26: PLT-024 | B26: P1 — Critique | C26: Modules activables par tenant — désactivation | D26: PUT /platform/tenants/:id/modules ; enforcement API (403 moduleDisabled) + sidebar masquée. | E26: superadmin connecté ; tenant SOTRA | F26: 1. Plateforme → Tenants → SOTRA → Modules → désactiver « Recrutement » 2. Se connecter admin@sotra.ci 3. Appeler GET /recruitment/jobs | G26: Entrée Recrutement absente de la sidebar ; API 403 { moduleDisabled: true } ; réactivation rétablit l'accès | O26: Recette 10/2026 | P26: Production
A27: PLT-025 | B27: P2 — Haute | C27: Modules opt-in — Vue DG 360°, Pointage, Simulations d'entretien | D27: dg_view, attendance, interview_sim désactivés par défaut. | E27: Nouveau tenant de test | F27: 1. Créer un tenant 2. Vérifier l'onglet Modules 3. Activer dg_view puis se connecter dg@ | G27: Les 3 modules sont OFF par défaut, tous les autres ON ; l'activation rend les pages accessibles | O27: Recette 10/2026 | P27: Production
A28: PLT-026 | B28: P2 — Haute | C28: Activation de modules en masse (bulk) | D28: POST /platform/tenants/modules-bulk. | E28: Plusieurs tenants | F28: 1. Sélectionner 2 tenants 2. Activer « Signature électronique » en masse | G28: Les 2 tenants reçoivent la surcharge ; clé de module inconnue refusée (400) | O28: Recette 10/2026 | P28: Production
A29: PLT-027 | B29: P1 — Critique | C29: Mise hors ligne d'un tenant avec message | D29: Suspension avec offline_message (variable système offline_message_default). | E29: Tenant de test | F29: 1. Tenant → Suspendre → saisir message « Maintenance contractuelle » 2. Vérifier login d'un utilisateur du tenant 3. Réactiver | G29: Message affiché aux utilisateurs bloqués ; filiales du tenant également bloquées ; si message obligatoire et vide → refus ; actions auditées | O29: Recette 10/2026 | P29: Production
A30: PLT-028 | B30: P2 — Haute | C30: Paramètres plateforme — politique de sécurité | D30: GET/PATCH /platform/settings (singleton). | E30: superadmin | F30: 1. Plateforme → Paramètres 2. Modifier MFA obligatoire, durée de vie mdp, historique, verrouillage, message hors ligne par défaut 3. Enregistrer puis recharger | G30: Valeurs persistées sur une seule ligne (pas de doublon) ; appliquées aux logins suivants | O30: Recette 10/2026 | P30: Production
A31: PLT-029 | B31: P2 — Haute | C31: Packs législatifs — consultation et modification | D31: GET/PATCH /platform/legislation-packs/:country. | E31: superadmin | F31: 1. Plateforme → Législation → pack CI 2. Consulter SMIG, préavis, barème ITS, taux CNPS 3. Modifier une valeur de test puis annuler | G31: Pack affiché complet ; modification validée et versionnée ; tenants CI recalculés avec la nouvelle valeur | O31: Recette 10/2026 | P31: Production
A32: PLT-030 | B32: P2 — Haute | C32: Propositions législatives — approbation / rejet | D32: legislation-proposals : approve/reject. | E32: Une proposition en attente | F32: 1. Plateforme → Législation → Propositions 2. Approuver une proposition, en rejeter une autre avec motif | G32: Statuts mis à jour, pack modifié uniquement après approbation, audit présent | O32: Recette 10/2026 | P32: Production
A33: PLT-031 | B33: P2 — Haute | C33: Veille légale IA — analyse de texte | D33: POST /platform/legal-watch/analyze (diff IA, confiance 0-100). | E33: superadmin ; IA disponible | F33: 1. Plateforme → Veille légale → coller un nouveau texte d'article 2. Lancer l'analyse 3. Coller un texte > 30 000 caractères | G33: Résumé des changements, confiance, raisonnement ; proposition créée ; texte trop long refusé (400) | O33: Recette 10/2026 | P33: Production
A34: PLT-032 | B34: P3 — Moyenne | C34: Constantes légales par pays et version | D34: GET/PATCH /platform/legal-constants/:country/:version. | E34: superadmin | F34: 1. Plateforme → Législation → Constantes 2. Modifier une constante d'une version future | G34: Constante enregistrée pour la version ciblée, version courante inchangée | O34: Recette 10/2026 | P34: Production
A35: PLT-033 | B35: P2 — Haute | C35: Configuration du sourcing IA (modèles, plateformes, réglages) | D35: Tables platform.sourcing_* — 100 % paramétrable. | E35: superadmin | F35: 1. Plateforme → Paramètres → Sourcing 2. Ajouter un modèle, désactiver une plateforme, modifier les réglages 3. Lancer un sourcing côté tenant | G35: Le sourcing utilise exactement la configuration (aucune valeur en dur) ; plateforme désactivée absente | O35: Recette 10/2026 | P35: Production
A36: PLT-034 | B36: P2 — Haute | C36: Export des données d'un tenant | D36: GET /platform/tenants/:id/export. | E36: superadmin | F36: 1. Tenant → Exporter les données | G36: Archive/JSON téléchargé contenant uniquement les données du tenant ciblé ; action auditée | O36: Recette 10/2026 | P36: Production
A37: PLT-035 | B37: P2 — Haute | C37: Suppression d'un tenant | D37: DELETE /platform/tenants/:id. | E37: Tenant de test créé pour l'occasion | F37: 1. Tenant de test → Supprimer → confirmer en saisissant le slug | G37: Tenant supprimé, schéma retiré, plus aucun login possible ; SOTRA intact | O37: Recette 10/2026 | P37: Production
... A41: PLT-039 | B41: P2 — Haute | C41: Consommation IA par tenant | D41: GET /platform/ai-usage (complément AI-104). | E41: superadmin ; tenants avec usage IA | F41: 1. Plateforme → Consommation IA 2. Filtrer par tenant et par mois | G41: Tokens et coût estimé par tenant/mois, aucune donnée de contenu des conversations exposée | O41: Recette 10/2026 | P41: Production

Sheet EMP
A1: GESTION DES EMPLOYÉS · 32 scénarios
A2: ID Test | B2: Priorité | C2: Titre du scénario | D2: Description / Contexte | E2: Prérequis / Données | F2: Étapes détaillées | G2: Résultat attendu | H2: Résultat obtenu | I2: Statut | J2: Testeur | K2: Date test | L2: Durée (min) | M2: Ticket / Requalification | N2: Commentaire / Amélioration | O2: Sprint | P2: Env.
A3: EMP-001 | B3: P1 — Critique | C3: Création employé — champs obligatoires | D3: Prénom, nom, email, département, poste, salaire brut FCFA | E3: Admin connecté, département créé | F3: 1. /employees/new 2. Remplir tous les champs requis 3. Sauvegarder | G3: Employé créé, visible dans la liste, aucune décimale dans le salaire | H3: Live: POST /employees valide -> 201 {data:{id, first_name, base_salary...}} ; employe visible en liste ; base_salary stocke en numeric(12,0) = entier (zero decimale). Champs requis: firstName, lastName, baseSalary (>=75000 SMIG CI). | I3: ✅ Passé | J3: Agents IA + live | K3: 23/06/2026 | O3: Sprint 1 | P3: Production
A4: EMP-002 | B4: P1 — Critique | C4: Email employé unique dans le tenant | F4: 1. Créer 2 employés avec le même email | G4: Erreur 409, message 'Email déjà utilisé dans ce tenant' | H4: Doublon email -> 409 (contrainte UNIQUE(email) intra-schema, catch 23505). Message: 'Un employe avec cet email existe deja.' (libelle canonique, coherent avec EMP-102 non-regression). | I4: ✅ Passé | J4: Agents IA + live | K4: 23/06/2026 | O4: Sprint 1 | P4: Production
A5: EMP-003 | B5: P2 — Haute | C5: Validation NNI — format ivoirien | D5: Format CI + 9 chiffres | F5: 1. Saisir NNI 'CI123456789' 2. Saisir NNI invalide 'AB12' | G5: NNI valide accepté, NNI invalide rejeté avec message d'erreur | H5: CORRIGE: le NNI n'avait aucune validation de format (seulement max(50)). Ajout regex /^CId{9,13}$/ : 'CI123456789' accepte, 'AB12' rejete avec message clair. NNI chiffre AES (RGPD). (Avant: 'AB12' echouait par accident en 22001 longueur ciphertext, message trompeur.) | I5: ✅ Passé | J5: Agents IA + correctif | K5: 23/06/2026 | O5: Sprint 1 | P5: Production
A6: EMP-004 | B6: P2 — Haute | C6: Validation CNPS — format CI | D6: Format CI + 8 chiffres + lettre | F6: 1. Saisir CI12345678A (valide) 2. Saisir 12345 (invalide) | G6: Valide accepté, invalide rejeté | H6: CORRIGE: le numero CNPS n'avait aucune validation. Ajout regex /^CId{8}[A-Z]$/ : 'CI12345678A' accepte, '12345' rejete avec message. | I6: ✅ Passé | J6: Agents IA + correctif | K6: 23/06/2026 | O6: Sprint 1 | P6: Production
A7: EMP-005 | B7: P2 — Haute | C7: Validation téléphone Mobile Money CI | D7: +225 07/05 + 8 chiffres | F7: 1. Saisir +225 07 12 34 56 78 (valide) 2. Saisir +33 6 12 (invalide) | G7: Format CI accepté, autre rejeté | H7: CORRIGE: le telephone Mobile Money n'etait pas valide a la saisie. Ajout validation indicatif AFRICAIN (CEDEAO+CEMAC+RDC : CI/BF/ML/NE/SN/TD/CG/RDC/CM...) car les employes peuvent venir de toute la zone ; +225/+226/+223/+235/+242 acceptes, +33/+1 rejetes ; espaces tolerees. | I7: ✅ Passé | J7: Agents IA + correctif | K7: 23/06/2026 | O7: Sprint 1 | P7: Production
A8: EMP-006 | B8: P1 — Critique | C8: Liste employés — pagination | D8: Affichage par page avec navigation | E8: 80+ employés SOTRA | F8: 1. Accéder /employees | G8: Pagination fonctionnelle, 20-50 par page, nombre total affiché | H8: CORRIGE: la liste renvoyait TOUS les employes (total=taille page). GET /employees pagine desormais (page/limit + COUNT reel) ; barre de pagination UI (prec/suiv + plage X-Y / total). Le total affiche est le vrai nombre du tenant (80+). | I8: ✅ Passé | J8: Agents IA + correctif | K8: 23/06/2026 | O8: Sprint 1 | P8: Production
A9: EMP-007 | B9: P1 — Critique | C9: Recherche employé par nom | D9: Champ de recherche filtrant en temps réel | F9: 1. Taper 'Kouassi' dans la recherche | G9: Liste filtrée aux employés correspondants | H9: Recherche par nom OK (live: 'Camara' -> 1 resultat). Backend ILIKE parametre (anti-injection) sur prenom/nom/cnps. Reserve mineure: pas de debounce (1 requete par frappe), non bloquant. | I9: ✅ Passé | J9: Agents IA + live | K9: 23/06/2026 | O9: Sprint 1 | P9: Production
A10: EMP-008 | B10: P2 — Haute | C10: Filtrage par département | D10: Sélecteur département | F10: 1. Sélectionner département 'Exploitation' 2. Observer la liste | G10: Seuls les employés du département Exploitation affichés | H10: CORRIGE: le filtre departement existait cote API (live OK: meme dept) mais aucun selecteur UI. Ajout d'un <select> departement (alimente par /employees/departments) cable a la requete, reset page au changement. | I10: ✅ Passé | J10: Agents IA + correctif | K10: 23/06/2026 | O10: Sprint 1 | P10: Production
A11: EMP-009 | B11: P1 — Critique | C11: Fiche employé — consultation | D11: Tous les champs visibles | F11: 1. Cliquer sur un employé dans la liste | G11: Fiche complète: identité, poste, salaire FCFA, NNI, CNPS, Mobile Money, ancienneté calculée | H11: CORRIGE: fiche complete (identite, poste, salaire FCFA, NNI dechiffre par role RH, CNPS, Mobile Money) mais ANCIENNETE non calculee. GET /employees/:id renvoie seniority_months + seniority_label (calcul depuis hire_date), affichee dans la fiche. (NB: nni null sur donnees seedees = seed-demo n'encrypte pas le nni - mineur.) | I11: ✅ Passé | J11: Agents IA + correctif | K11: 23/06/2026 | O11: Sprint 1 | P11: Production
A12: EMP-010 | B12: P1 — Critique | C12: Modification employé | D12: Mise à jour des données | F12: 1. Ouvrir fiche 2. Modifier salaire 3. Sauvegarder | G12: Données mises à jour, historique hr_events enregistré | H12: CORRIGE: modifier le salaire (live: PATCH 200, salaire mis a jour) ne creait AUCUN hr_events. PATCH /employees/:id capture l'ancien salaire et insere un hr_events (augmentation/salary_change avec ancien/nouveau montant, non bloquant). Historique RH desormais alimente. | I12: ✅ Passé | J12: Agents IA + correctif | K12: 23/06/2026 | O12: Sprint 1 | P12: Production
A13: EMP-011 | B13: P2 — Haute | C13: Désactivation employé | D13: is_active = false, employé absent des listings actifs | F13: 1. Fiche employé → Désactiver | G13: Employé marqué inactif, n'apparaît plus dans liste active | H13: Live: PATCH /employees/:id isActive=false -> l'employe disparait de la liste active (GET ?isActive=true ne le contient plus). Le compte user lie est aussi desactive (cf. DELETE/archive employe). | I13: ✅ Passé | J13: Agents IA + live | K13: 23/06/2026 | O13: Sprint 1 | P13: Production
A14: EMP-012 | B14: P2 — Haute | C14: Calcul ancienneté affiché | D14: Années et mois depuis hire_date | F14: 1. Ouvrir fiche employé embauché il y a 3 ans 2 mois | G14: Affiche '3 ans 2 mois' correctement | H14: Live: employe embauche le 2023-04-23 (il y a 3 ans 2 mois) -> GET /employees/:id renvoie seniority_months=38, seniority_label='3 an(s) 2 mois' ; affiche correctement dans la fiche. (Corrige via EMP-009.) | I14: ✅ Passé | J14: Agents IA + live | K14: 23/06/2026 | O14: Sprint 1 | P14: Production
A15: EMP-013 | B15: P3 — Moyenne | C15: Import CSV employés | D15: Upload d'un fichier CSV pour création en masse | E15: Fichier CSV valide préparé | F15: 1. /employees/import 2. Uploader CSV 3. Valider | G15: Employés créés en masse, rapport d'import (succès/erreurs) | H15: CORRIGE (decouvrabilite): l'import CSV de masse EXISTE et fonctionne (Parametres > Reprise de donnees, POST /settings/import/employees : creation en masse + rapport succes/erreurs par ligne, chiffrement IBAN, RBAC). Ajout d'un bouton 'Importer' sur la page Employes qui ouvre l'onglet d'import (/settings?tab=data-import). | I15: ✅ Passé | J15: Agents IA + correctif | K15: 23/06/2026 | O15: Sprint 1 | P15: Production
A16: EMP-014 | B16: P3 — Moyenne | C16: Export liste employés | D16: Téléchargement CSV/Excel | F16: 1. Bouton Export dans la liste 2. Choisir format | G16: Fichier téléchargé avec tous les champs, encodage UTF-8, FCFA entiers | H16: CORRIGE: aucun export de la liste. Ajout GET /employees/export.csv (BOM UTF-8 pour Excel FR, anti-injection CSV via encodeField, salaires FCFA ENTIERS via Math.round, NNI/IBAN EXCLUS pour RGPD) + bouton 'Exporter' (telechargement blob). RBAC admin/hr_manager/hr_officer. | I16: ✅ Passé | J16: Agents IA + correctif | K16: 23/06/2026 | O16: Sprint 1 | P16: Production
A17: EMP-015 | B17: P3 — Moyenne | C17: Upload photo profil | D17: Image recadrée et sauvegardée | F17: 1. Fiche employé → Photo 2. Uploader une image 3. Recadrer 4. Sauvegarder | G17: Photo visible dans la fiche et dans le header | H17: CORRIGE: aucune photo de profil (champ existait mais ni endpoint, ni UI, ni affichage). Ajout POST /employees/:id/photo (multipart, allowlist PNG/JPEG/WEBP/GIF, max 2Mo, RBAC RH+self, SVG exclu anti-XSS) + l'avatar de la fiche affiche la VRAIE photo (fallback initiales) avec bouton d'upload (icone appareil photo). Recadrage avance non inclus (P3). | I17: ✅ Passé | J17: Agents IA + correctif | K17: 23/06/2026 | O17: Sprint 1 | P17: Production
A18: EMP-016 | B18: P1 — Critique | C18: Manager ne voit que son équipe | D18: Filtrage automatique par department_id du manager | E18: manager@sotra.ci lié à département Exploitation | F18: 1. Connecter manager@sotra.ci 2. Accéder /employees | G18: Seuls les employés de son département listés | H18: Manager filtre fail-closed: ne voit que son EQUIPE DIRECTE (e.manager_id = id de l'employe lie au manager via email du JWT). Si pas de dossier lie -> liste vide/403 (pas tout le tenant). COUNT partage le meme WHERE. Fiche /:id refuse aussi hors-equipe (403). NNI/IBAN masques au manager. | I18: ✅ Passé | J18: Agents IA (code) | K18: 23/06/2026 | O18: Sprint 1 | P18: Production
A19: EMP-017 | B19: P1 — Critique | C19: Employee ne peut pas accéder /employees | D19: Redirection /mon-espace | F19: 1. Connecter employe@sotra.ci 2. Tenter /employees | G19: Redirection automatique vers /mon-espace | H19: Employee bloque de /employees: RoleGuard (allowedRoles sans 'employee') -> /dashboard -> RhDashboardGuard -> /mon-espace (chaine deterministe, sans boucle). Backend defense-in-depth: GET /employees authorize sans 'employee' -> 403. | I19: ✅ Passé | J19: Agents IA (code) | K19: 23/06/2026 | O19: Sprint 1 | P19: Production
